[ERROR]2023.05.07 15:17:02 : python执行的错误信息("Connection broken: ConnectionResetError(10054, '远程主机强迫关闭了一个现有的连接。', None, 10054, None)", ConnectionResetError(10054, '远程主机强迫关闭了一个现有的连接。', None, 10054, None))
[ERROR]2023.05.07 15:18:06 : python执行的错误信息HTTPConnectionPool(host='192.168.3.22', port=9004): Max retries exceeded with url: /api/eod/all-business-date (Caused by ConnectTimeoutError(<urllib3.connection.HTTPConnection object at 0x0000016B0C913580>, 'Connection to 192.168.3.22 timed out. (connect timeout=None)'))
[ERROR]2023.05.07 15:18:06 : python执行时的错误：'ConnectTimeout' object has no attribute 'status_code'
